<?xml version="1.0" ?>
<robot name="caba" xmlns:xacro="http://www.ros.org/wiki/xacro">

<xacro:include filename="$(find caba_description)/urdf/materials.xacro" />
<xacro:include filename="$(find caba_description)/urdf/caba.trans" />
<xacro:include filename="$(find caba_description)/urdf/caba.gazebo" />

<link name="base_link">
  <inertial>
    <origin rpy="0 0 0" xyz="-0.0011847288991747743 7.185810134250719e-11 0.06883632762905934"/>
    <mass value="9.999263199204597"/>
    <inertia ixx="0.203031" ixy="1e-05" ixz="0.000313" iyy="0.297481" iyz="0.0" izz="0.391257"/>
  </inertial>
  <visual>
    <origin rpy="0 0 0" xyz="0 0 0"/>
    <geometry>
      <mesh filename="package://caba_description/meshes/base_link.stl" scale="0.001 0.001 0.001"/>
    </geometry>
    <material name="silver"/>
  </visual>
  <collision>
    <origin rpy="0 0 0" xyz="0 0 0"/>
    <geometry>
      <mesh filename="package://caba_description/meshes/base_link.stl" scale="0.001 0.001 0.001"/>
    </geometry>
  </collision>
</link>

<link name="right_wheel_1">
  <inertial>
    <origin rpy="0 0 0" xyz="2.2861500076694515e-07 0.0040000000000000036 -3.2082938715427556e-08"/>
    <mass value="0.03725143488994098"/>
    <inertia ixx="1.5e-05" ixy="-0.0" ixz="0.0" iyy="3e-05" iyz="0.0" izz="1.5e-05"/>
  </inertial>
  <visual>
    <origin rpy="0 0 0" xyz="-8.5e-05 0.1965 0.029407"/>
    <geometry>
      <mesh filename="package://caba_description/meshes/right_wheel_1.stl" scale="0.001 0.001 0.001"/>
    </geometry>
    <material name="silver"/>
  </visual>
  <collision>
    <origin rpy="0 0 0" xyz="-8.5e-05 0.1965 0.029407"/>
    <geometry>
      <mesh filename="package://caba_description/meshes/right_wheel_1.stl" scale="0.001 0.001 0.001"/>
    </geometry>
  </collision>
</link>

<link name="left_wheel_1">
  <inertial>
    <origin rpy="0 0 0" xyz="-2.2861500079528348e-07 -0.003999999999999976 -3.208293869808032e-08"/>
    <mass value="0.037251434889940996"/>
    <inertia ixx="1.5e-05" ixy="0.0" ixz="0.0" iyy="3e-05" iyz="0.0" izz="1.5e-05"/>
  </inertial>
  <visual>
    <origin rpy="0 0 0" xyz="8.5e-05 -0.1965 0.029407"/>
    <geometry>
      <mesh filename="package://caba_description/meshes/left_wheel_1.stl" scale="0.001 0.001 0.001"/>
    </geometry>
    <material name="silver"/>
  </visual>
  <collision>
    <origin rpy="0 0 0" xyz="8.5e-05 -0.1965 0.029407"/>
    <geometry>
      <mesh filename="package://caba_description/meshes/left_wheel_1.stl" scale="0.001 0.001 0.001"/>
    </geometry>
  </collision>
</link>

<link name="laser">
  <inertial>
    <origin rpy="0 0 0" xyz="0.006854802401513253 -0.0010802476481471532 0.026568901965641684"/>
    <mass value="0.11522595365537097"/>
    <inertia ixx="5.3e-05" ixy="-1e-06" ixz="1.3e-05" iyy="9.5e-05" iyz="1e-06" izz="0.000111"/>
  </inertial>
  <visual>
    <origin rpy="0 0 0" xyz="0.001655 -0.0 -0.179"/>
    <geometry>
      <mesh filename="package://caba_description/meshes/rplidar_1.stl" scale="0.001 0.001 0.001"/>
    </geometry>
    <material name="silver"/>
  </visual>
  <collision>
    <origin rpy="0 0 0" xyz="0.001655 -0.0 -0.179"/>
    <geometry>
      <mesh filename="package://caba_description/meshes/rplidar_1.stl" scale="0.001 0.001 0.001"/>
    </geometry>
  </collision>
</link>

<link name="front_caster_tire_1">
  <inertial>
    <origin rpy="0 0 0" xyz="0.0438567830429589 0.006514756553844138 -0.07349107828745045"/>
    <mass value="0.019114076713434056"/>
    <inertia ixx="5.7e-05" ixy="0.0" ixz="-0.0" iyy="2.3e-05" iyz="0.0" izz="6.3e-05"/>
  </inertial>
  <visual>
    <origin rpy="0 0 0" xyz="-0.221938 -0.011 0.0495"/>
    <geometry>
      <mesh filename="package://caba_description/meshes/front_caster_tire_1.stl" scale="0.001 0.001 0.001"/>
    </geometry>
    <material name="silver"/>
  </visual>
  <collision>
    <origin rpy="0 0 0" xyz="-0.221938 -0.011 0.0495"/>
    <geometry>
      <mesh filename="package://caba_description/meshes/front_caster_tire_1.stl" scale="0.001 0.001 0.001"/>
    </geometry>
  </collision>
</link>

<link name="front_caster_body_1">
  <inertial>
    <origin rpy="0 0 0" xyz="-0.191795 0.0 0.002"/>
    <mass value="0.1"/>
    <inertia ixx="0.0" ixy="0.0" ixz="0.0" iyy="0.0" iyz="0.0" izz="0.0"/>
  </inertial>
  <visual>
    <origin rpy="0 0 0" xyz="-0.191795 -0.0 0.002"/>
    <geometry>
      <mesh filename="package://caba_description/meshes/front_caster_body_1.stl" scale="0.001 0.001 0.001"/>
    </geometry>
    <material name="silver"/>
  </visual>
  <collision>
    <origin rpy="0 0 0" xyz="-0.191795 -0.0 0.002"/>
    <geometry>
      <mesh filename="package://caba_description/meshes/front_caster_body_1.stl" scale="0.001 0.001 0.001"/>
    </geometry>
  </collision>
</link>

<link name="rear_caster_body_1">
  <inertial>
    <origin rpy="0 0 0" xyz="0.201795 0.0 0.002"/>
    <mass value="0.1"/>
    <inertia ixx="0.0" ixy="0.0" ixz="0.0" iyy="0.0" iyz="0.0" izz="0.0"/>
  </inertial>
  <visual>
    <origin rpy="0 0 0" xyz="0.201795 -0.0 0.002"/>
    <geometry>
      <mesh filename="package://caba_description/meshes/rear_caster_body_1.stl" scale="0.001 0.001 0.001"/>
    </geometry>
    <material name="silver"/>
  </visual>
  <collision>
    <origin rpy="0 0 0" xyz="0.201795 -0.0 0.002"/>
    <geometry>
      <mesh filename="package://caba_description/meshes/rear_caster_body_1.stl" scale="0.001 0.001 0.001"/>
    </geometry>
  </collision>
</link>

<link name="rear_caster_tire_1">
  <inertial>
    <origin rpy="0 0 0" xyz="6.873565389642344e-07 -0.010500244051253481 -7.813111250337679e-08"/>
    <mass value="0.019114076713376713"/>
    <inertia ixx="5.7e-05" ixy="0.0" ixz="0.0" iyy="2.3e-05" iyz="-0.0" izz="6.3e-05"/>
  </inertial>
  <visual>
    <origin rpy="0 0 0" xyz="0.171738 -0.011 0.0495"/>
    <geometry>
      <mesh filename="package://caba_description/meshes/rear_caster_tire_1.stl" scale="0.001 0.001 0.001"/>
    </geometry>
    <material name="silver"/>
  </visual>
  <collision>
    <origin rpy="0 0 0" xyz="0.171738 -0.011 0.0495"/>
    <geometry>
      <mesh filename="package://caba_description/meshes/rear_caster_tire_1.stl" scale="0.001 0.001 0.001"/>
    </geometry>
  </collision>
</link>

<joint name="right_wheel_joint" type="continuous">
  <origin rpy="0 0 0" xyz="8.5e-05 -0.1965 -0.029407"/>
  <parent link="base_link"/>
  <child link="right_wheel_1"/>
  <axis xyz="0.0 1.0 0.0"/>
</joint>

<joint name="left_wheel_joint" type="continuous">
  <origin rpy="0 0 0" xyz="-8.5e-05 0.1965 -0.029407"/>
  <parent link="base_link"/>
  <child link="left_wheel_1"/>
  <axis xyz="0.0 1.0 0.0"/>
</joint>

<joint name="lidar_joint" type="fixed">
  <origin rpy="0 0 0" xyz="-0.001655 0.0 0.179"/>
  <parent link="base_link"/>
  <child link="laser"/>
</joint>

<joint name="front_caster_wheel_joint" type="continuous">
  <origin rpy="0 0 0" xyz="0.030057 0.011 -0.0475"/>
  <parent link="front_caster_body_1"/>
  <child link="front_caster_tire_1"/>
  <axis xyz="0.0 1.0 -0.0"/>
</joint>

<joint name="front_caster_body_joint" type="continuous">
  <origin rpy="0 0 0" xyz="0.191795 0.0 -0.001"/>
  <parent link="base_link"/>
  <child link="front_caster_body_1"/>
  <axis xyz="0.0 0.0 1.0"/>
</joint>

<joint name="rear_caster_body_joint" type="continuous">
  <origin rpy="0 0 0" xyz="-0.191795 0.0 -0.001"/>
  <parent link="base_link"/>
  <child link="rear_caster_body_1"/>
  <axis xyz="0.0 0.0 1.0"/>
</joint>

<joint name="rear_caster_wheel_joint" type="continuous">
  <origin rpy="0 0 0" xyz="0.030057 0.011 -0.0475"/>
  <parent link="rear_caster_body_1"/>
  <child link="rear_caster_tire_1"/>
  <axis xyz="-0.0 1.0 0.0"/>
</joint>

</robot>
